<?xml version="1.0" encoding="UTF-8"?>
<!-- Generated by org.testng.reporters.JUnitReportReporter -->
<testsuite hostname="AyeshAmir" failures="2" tests="5" name="testCases.TC003_loginDDT" time="37.932" errors="0" timestamp="2025-09-12T18:17:22 IST" skipped="0">
  <testcase classname="testCases.TC003_loginDDT" name="verify_loginDDT" time="0.738">
    <failure message="null" type="java.lang.AssertionError">
      <![CDATA[java.lang.AssertionError: null
at org.testng.Assert.fail(Assert.java:111)
at org.testng.Assert.fail(Assert.java:116)
at testCases.TC003_loginDDT.verify_loginDDT(TC003_loginDDT.java:55)
at java.base/jdk.internal.reflect.NativeMethodAccessorImpl.invoke0(Native Method)
at java.base/jdk.internal.reflect.NativeMethodAccessorImpl.invoke(NativeMethodAccessorImpl.java:62)
at java.base/jdk.internal.reflect.DelegatingMethodAccessorImpl.invoke(DelegatingMethodAccessorImpl.java:43)
at java.base/java.lang.reflect.Method.invoke(Method.java:566)
at org.testng.internal.invokers.MethodInvocationHelper.invokeMethod(MethodInvocationHelper.java:139)
at org.testng.internal.invokers.TestInvoker.invokeMethod(TestInvoker.java:664)
at org.testng.internal.invokers.TestInvoker.invokeTestMethod(TestInvoker.java:228)
at org.testng.internal.invokers.MethodRunner.runInSequence(MethodRunner.java:63)
at org.testng.internal.invokers.TestInvoker$MethodInvocationAgent.invoke(TestInvoker.java:961)
at org.testng.internal.invokers.TestInvoker.invokeTestMethods(TestInvoker.java:201)
at org.testng.internal.invokers.TestMethodWorker.invokeTestMethods(TestMethodWorker.java:148)
at org.testng.internal.invokers.TestMethodWorker.run(TestMethodWorker.java:128)
at java.base/java.util.ArrayList.forEach(ArrayList.java:1541)
at org.testng.TestRunner.privateRun(TestRunner.java:819)
at org.testng.TestRunner.run(TestRunner.java:619)
at org.testng.SuiteRunner.runTest(SuiteRunner.java:443)
at org.testng.SuiteRunner$SuiteWorker.run(SuiteRunner.java:481)
at org.testng.internal.thread.ThreadUtil.lambda$execute$0(ThreadUtil.java:58)
at java.base/java.util.concurrent.FutureTask.run(FutureTask.java:264)
at java.base/java.util.concurrent.ThreadPoolExecutor.runWorker(ThreadPoolExecutor.java:1128)
at java.base/java.util.concurrent.ThreadPoolExecutor$Worker.run(ThreadPoolExecutor.java:628)
at java.base/java.lang.Thread.run(Thread.java:834)
]]>
    </failure>
  </testcase> <!-- verify_loginDDT -->
  <testcase classname="testCases.TC003_loginDDT" name="verify_loginDDT" time="11.658"/>
  <testcase classname="testCases.TC003_loginDDT" name="verify_loginDDT" time="11.739">
    <failure message="expected [true] but found [false]" type="java.lang.AssertionError">
      <![CDATA[java.lang.AssertionError: expected [true] but found [false]
at org.testng.Assert.fail(Assert.java:111)
at org.testng.Assert.failNotEquals(Assert.java:1578)
at org.testng.Assert.assertTrue(Assert.java:57)
at org.testng.Assert.assertTrue(Assert.java:67)
at testCases.TC003_loginDDT.verify_loginDDT(TC003_loginDDT.java:41)
at java.base/jdk.internal.reflect.NativeMethodAccessorImpl.invoke0(Native Method)
at java.base/jdk.internal.reflect.NativeMethodAccessorImpl.invoke(NativeMethodAccessorImpl.java:62)
at java.base/jdk.internal.reflect.DelegatingMethodAccessorImpl.invoke(DelegatingMethodAccessorImpl.java:43)
at java.base/java.lang.reflect.Method.invoke(Method.java:566)
at org.testng.internal.invokers.MethodInvocationHelper.invokeMethod(MethodInvocationHelper.java:139)
at org.testng.internal.invokers.TestInvoker.invokeMethod(TestInvoker.java:664)
at org.testng.internal.invokers.TestInvoker.invokeTestMethod(TestInvoker.java:228)
at org.testng.internal.invokers.MethodRunner.runInSequence(MethodRunner.java:63)
at org.testng.internal.invokers.TestInvoker$MethodInvocationAgent.invoke(TestInvoker.java:961)
at org.testng.internal.invokers.TestInvoker.invokeTestMethods(TestInvoker.java:201)
at org.testng.internal.invokers.TestMethodWorker.invokeTestMethods(TestMethodWorker.java:148)
at org.testng.internal.invokers.TestMethodWorker.run(TestMethodWorker.java:128)
at java.base/java.util.ArrayList.forEach(ArrayList.java:1541)
at org.testng.TestRunner.privateRun(TestRunner.java:819)
at org.testng.TestRunner.run(TestRunner.java:619)
at org.testng.SuiteRunner.runTest(SuiteRunner.java:443)
at org.testng.SuiteRunner$SuiteWorker.run(SuiteRunner.java:481)
at org.testng.internal.thread.ThreadUtil.lambda$execute$0(ThreadUtil.java:58)
at java.base/java.util.concurrent.FutureTask.run(FutureTask.java:264)
at java.base/java.util.concurrent.ThreadPoolExecutor.runWorker(ThreadPoolExecutor.java:1128)
at java.base/java.util.concurrent.ThreadPoolExecutor$Worker.run(ThreadPoolExecutor.java:628)
at java.base/java.lang.Thread.run(Thread.java:834)
]]>
    </failure>
  </testcase> <!-- verify_loginDDT -->
  <testcase classname="testCases.TC003_loginDDT" name="verify_loginDDT" time="2.240"/>
  <testcase classname="testCases.TC003_loginDDT" name="verify_loginDDT" time="11.557"/>
</testsuite> <!-- testCases.TC003_loginDDT -->
